<sdf version='1.4'>
  <model name='robotino'>
    <link name='base_link'>
      <pose>0 0 0 0 -0 0</pose>
      <inertial>
        <pose>0 0 0.5 0 -0 0</pose>
        <mass>20</mass>
        <inertia>
          <ixx>1</ixx>
          <ixy>0</ixy>
          <ixz>0</ixz>
          <iyy>1</iyy>
          <iyz>0</iyz>
          <izz>1</izz>
        </inertia>
      </inertial>
      <visual name='base_link_visual'>
        <pose>0 0 0.1 0 -0 1.57079</pose>
        <geometry>
          <box>
            <size>0.05 0.1 0.02</size>
          </box>
        </geometry>
      </visual>
      <velocity_decay>
        <linear>0</linear>
        <angular>0</angular>
      </velocity_decay>
    </link>
    <link name='wheel0_link'>
      <pose>-0.13 0 0.04 0 -0 0</pose>
      <inertial>
        <pose>0 0 0 0 -0 0</pose>
        <mass>0.3</mass>
        <inertia>
          <ixx>1</ixx>
          <ixy>0</ixy>
          <ixz>0</ixz>
          <iyy>1</iyy>
          <iyz>0</iyz>
          <izz>1</izz>
        </inertia>
      </inertial>
      <collision name='wheel0_link_collision'>
        <pose>0 0 0 1.57079 -0 1.57079</pose>
        <geometry>
          <cylinder>
            <length>0.0001</length>
            <radius>0.04</radius>
          </cylinder>
        </geometry>
        <surface>
          <contact>
            <ode>
              <kp>1e+06</kp>
              <kd>100</kd>
            </ode>
          </contact>
          <friction>
            <ode>
              <mu>5</mu>
              <mu2>0</mu2>
              <fdir1>1 0 0</fdir1>
              <slip1>0</slip1>
              <slip2>1</slip2>
            </ode>
          </friction>
        </surface>
      </collision>
      <gravity>1</gravity>
      <velocity_decay>
        <linear>0</linear>
        <angular>0</angular>
      </velocity_decay>
      <self_collide>0</self_collide>
    </link>
    <joint name='wheel0_joint' type='revolute'>
      <child>wheel0_link</child>
      <parent>base_link</parent>
      <axis>
        <xyz>-1 0 0</xyz>
        <limit>
          <lower>-1e+16</lower>
          <upper>1e+16</upper>
        </limit>
        <dynamics/>
      </axis>
    </joint>
    <link name='wheel1_link'>
      <pose>0.065 0.11 0.04 0 -0 1.0472</pose>
      <inertial>
        <pose>0 0 0 0 -0 0</pose>
        <mass>0.3</mass>
        <inertia>
          <ixx>1</ixx>
          <ixy>0</ixy>
          <ixz>0</ixz>
          <iyy>1</iyy>
          <iyz>0</iyz>
          <izz>1</izz>
        </inertia>
      </inertial>
      <collision name='wheel1_link_collision'>
        <pose>0 0 0 1.57079 -0 1.57079</pose>
        <geometry>
          <cylinder>
            <length>0.0001</length>
            <radius>0.04</radius>
          </cylinder>
        </geometry>
        <surface>
          <contact>
            <ode>
              <kp>1e+06</kp>
              <kd>100</kd>
            </ode>
          </contact>
          <friction>
            <ode>
              <mu>5</mu>
              <mu2>0</mu2>
              <fdir1>1 0 0</fdir1>
              <slip1>0</slip1>
              <slip2>1</slip2>
            </ode>
          </friction>
        </surface>
      </collision>
      <gravity>1</gravity>
      <velocity_decay>
        <linear>0</linear>
        <angular>0</angular>
      </velocity_decay>
      <self_collide>0</self_collide>
    </link>
    <joint name='wheel1_joint' type='revolute'>
      <child>wheel1_link</child>
      <parent>base_link</parent>
      <axis>
        <xyz>0.500001 0.866025 0</xyz>
        <limit>
          <lower>-1e+16</lower>
          <upper>1e+16</upper>
        </limit>
        <dynamics/>
      </axis>
    </joint>
    <link name='wheel2_link'>
      <pose>0.065 -0.11 0.04 0 0 -1.0472</pose>
      <inertial>
        <pose>0 0 0 0 -0 0</pose>
        <mass>0.3</mass>
        <inertia>
          <ixx>1</ixx>
          <ixy>0</ixy>
          <ixz>0</ixz>
          <iyy>1</iyy>
          <iyz>0</iyz>
          <izz>1</izz>
        </inertia>
      </inertial>
      <collision name='wheel2_link_collision'>
        <pose>0 0 0 1.57079 -0 1.57079</pose>
        <geometry>
          <cylinder>
            <length>0.0001</length>
            <radius>0.04</radius>
          </cylinder>
        </geometry>
        <surface>
          <contact>
            <ode>
              <max_vel>1</max_vel>
              <min_depth>0</min_depth>
            </ode>
          </contact>
          <friction>
            <ode>
              <mu>0.3</mu>
              <mu2>0</mu2>
              <fdir1>1 0 0</fdir1>
              <slip1>0</slip1>
              <slip2>1</slip2>
            </ode>
          </friction>
        </surface>
      </collision>
      <gravity>1</gravity>
      <velocity_decay>
        <linear>0</linear>
        <angular>0</angular>
      </velocity_decay>
      <self_collide>0</self_collide>
    </link>
    <joint name='wheel2_joint' type='revolute'>
      <child>wheel2_link</child>
      <parent>base_link</parent>
      <axis>
        <xyz>0.500001 -0.866025 0</xyz>
        <limit>
          <lower>-1e+16</lower>
          <upper>1e+16</upper>
        </limit>
        <dynamics/>
      </axis>
    </joint>
    <static>0</static>
    <plugin name='robotino_plugin' filename='librobotino_plugin.so'/>
  </model>
</sdf>
