<?xml version="1.0" ?>
<!-- =================================================================================== -->
<!-- |    This document was autogenerated by xacro from /home/leak/Projets/catkin_ws/src/pyro-robotino/robotino3_description/urdf/robotino.urdf.xacro | -->
<!-- |    EDITING THIS FILE BY HAND IS NOT RECOMMENDED                                 | -->
<!-- =================================================================================== -->
<robot name="robotino" xmlns:xacro="http://www.ros.org/wiki/xacro">
  <!-- Import all Gazebo-customization elements, including Gazebo colors -->
  <gazebo reference="wheel0_link">
    <kp>1000000.0</kp>
    <kd>100.0</kd>
    <mu1>5</mu1>
    <mu2>0</mu2>
    <fdir1>1 0 0</fdir1>
  </gazebo>
  <gazebo reference="wheel1_link">
    <kp>1000000.0</kp>
    <kd>100.0</kd>
    <mu1>5</mu1>
    <mu2>0</mu2>
    <fdir1>1 0 0</fdir1>
  </gazebo>
  <gazebo reference="wheel2_link">
    <!--     <kp>1000000.0</kp>
    <kd>100.0</kd> -->
    <mu1>0.3</mu1>
    <mu2>0</mu2>
    <fdir1>1 0 0</fdir1>
    <maxVel>1.0</maxVel>
    <minDepth>0.00</minDepth>
  </gazebo>
  <gazebo>
    <plugin filename="librobotino_plugin.so" name="robotino_plugin"/>
  </gazebo>
  <!-- Include files -->
  <link name="base_link">
    <inertial>
      <mass value="20"/>
      <origin xyz="0 0 0.5"/>
      <inertia ixx="1.0" ixy="0.0" ixz="0.0" iyy="1.0" iyz="0.0" izz="1.0"/>
    </inertial>
    <!--       <visual>
        <origin xyz="0.01 0 0" rpy="0 0 ${M_PI/2}"/>
        <geometry>
          <mesh filename="package://robotino3_description/meshes/RobotinoBody.dae" scale="${M_SCALE} ${M_SCALE} ${M_SCALE}"/>
        </geometry>
      </visual> -->
    <visual>
      <origin rpy="0 0 1.570795" xyz="0 0 0.1"/>
      <geometry>
        <box size="0.05 0.1 0.02"/>
      </geometry>
    </visual>
    <!--       <collision>
        <origin xyz="0 0 ${BASE_HEIGHT/2 + 0.03}" rpy="0 0 0" />
        <geometry>
          <cylinder radius="${BASE_RADIUS}" length="${BASE_HEIGHT}"/>
        </geometry>
      </collision> -->
  </link>
  <joint name="wheel1_joint" type="continuous">
    <!-- type continuous -->
    <origin rpy="0 0 1.04719666667" xyz="0.065 0.11 0.04"/>
    <axis xyz="1 0 0"/>
    <parent link="base_link"/>
    <child link="wheel1_link"/>
  </joint>
  <link name="wheel1_link">
    <inertial>
      <mass value="0.3"/>
      <origin xyz="0 0 0"/>
      <inertia ixx="1.0" ixy="0.0" ixz="0.0" iyy="1.0" iyz="0.0" izz="1.0"/>
    </inertial>
    <!--       <visual>
        <origin xyz="0 0 0" rpy="0 0 0" />
        <geometry>
          <mesh filename="package://robotino3_description/meshes/RobotinoWheel.dae" scale="${M_SCALE} ${M_SCALE} ${M_SCALE}"/>
        </geometry>
      </visual> -->
    <collision>
      <origin rpy="1.570795 0 1.570795" xyz="0 0 0"/>
      <geometry>
        <cylinder length="0.0001" radius="0.04"/>
      </geometry>
    </collision>
    <!--       <collision>
        <origin xyz="0 0 0" rpy="0 0 0" />
        <geometry>
          <mesh filename="package://robotino3_description/meshes/RobotinoWheel.dae" scale="${M_SCALE} ${M_SCALE} ${M_SCALE}"/>
        </geometry>
      </collision> -->
  </link>
  <joint name="wheel0_joint" type="continuous">
    <!-- type continuous -->
    <origin rpy="0 0 0" xyz="-0.13 0 0.04"/>
    <axis xyz="-1 0 0"/>
    <parent link="base_link"/>
    <child link="wheel0_link"/>
  </joint>
  <link name="wheel0_link">
    <inertial>
      <mass value="0.3"/>
      <origin xyz="0 0 0"/>
      <inertia ixx="1.0" ixy="0.0" ixz="0.0" iyy="1.0" iyz="0.0" izz="1.0"/>
    </inertial>
    <!--       <visual>
        <origin xyz="0 0 0" rpy="0 0 0" />
        <geometry>
          <mesh filename="package://robotino3_description/meshes/RobotinoWheel.dae" scale="${M_SCALE} ${M_SCALE} ${M_SCALE}"/>
        </geometry>
      </visual> -->
    <collision>
      <origin rpy="1.570795 0 1.570795" xyz="0 0 0"/>
      <geometry>
        <cylinder length="0.0001" radius="0.04"/>
      </geometry>
    </collision>
    <!--       <collision>
        <origin xyz="0 0 0" rpy="0 0 0" />
        <geometry>
          <mesh filename="package://robotino3_description/meshes/RobotinoWheel.dae" scale="${M_SCALE} ${M_SCALE} ${M_SCALE}"/>
        </geometry>
      </collision> -->
  </link>
  <joint name="wheel2_joint" type="continuous">
    <!-- type continuous -->
    <origin rpy="0 0 -1.04719666667" xyz="0.065 -0.11 0.04"/>
    <axis xyz="1 0 0"/>
    <parent link="base_link"/>
    <child link="wheel2_link"/>
  </joint>
  <link name="wheel2_link">
    <inertial>
      <mass value="0.3"/>
      <origin xyz="0 0 0"/>
      <inertia ixx="1.0" ixy="0.0" ixz="0.0" iyy="1.0" iyz="0.0" izz="1.0"/>
    </inertial>
    <!--       <visual>
        <origin xyz="0 0 0" rpy="0 0 0" />
        <geometry>
          <mesh filename="package://robotino3_description/meshes/RobotinoWheel.dae" scale="${M_SCALE} ${M_SCALE} ${M_SCALE}"/>
        </geometry>
      </visual> -->
    <collision>
      <origin rpy="1.570795 0 1.570795" xyz="0 0 0"/>
      <geometry>
        <cylinder length="0.0001" radius="0.04"/>
      </geometry>
    </collision>
    <!--       <collision>
        <origin xyz="0 0 0" rpy="0 0 0" />
        <geometry>
          <mesh filename="package://robotino3_description/meshes/RobotinoWheel.dae" scale="${M_SCALE} ${M_SCALE} ${M_SCALE}"/>
        </geometry>
      </collision> -->
  </link>
</robot>
